test_0 (__main__.lab1a.test_0)
[Lab 1] - [Investigation 3] - [Part 2] - printing - Test for file creation: ./lab1a.py ... FAIL

======================================================================
FAIL: test_0 (__main__.lab1a.test_0)
[Lab 1] - [Investigation 3] - [Part 2] - printing - Test for file creation: ./lab1a.py
----------------------------------------------------------------------
Traceback (most recent call last):
  File "/home/sjdujua/my-first-repo-lab1/./CheckLab1.py", line 60, in test_0
    self.assertTrue(os.path.exists('./lab1a.py'), msg=error_output)
AssertionError: False is not true : your file cannot be found(HINT: make sure you AND your file are in the correct directory)

----------------------------------------------------------------------
Ran 1 test in 0.000s

FAILED (failures=1)
OPS445 Lab Report - System Information for running ./CheckLab1.py
=================================================================
    User login name: sjdujua
    Git Email: sjdujua@myseneca.ca
    Linux system name: sjdujua-VirtualBox
    Python executable: /usr/bin/python3
    Python version:  3.12.3 (main, Nov  6 2024, 18:32:19) [GCC 13.2.0]
    OS Platform: linux
    Working Directory: /home/sjdujua/my-first-repo-lab1
    Start at: Sat Jan 11 22:29:02 2025
=================================================================
